{"name": "test0001", "status": "broken", "statusDetails": {"message": "RuntimeError: 'cryptography' package is required for sha256_password or caching_sha2_password auth methods", "trace": "self = <script.api.test_add_course.TestAddCourse object at 0x000002316ED5DAB0>\n\n    def test0001(self):\n>       operationsMYSQL = OperationsMYSQL()\n\ntest_add_course.py:39: \n_ _ _ _ _ _ _ _ _ _ _ _ _ _ _ _ _ _ _ _ _ _ _ _ _ _ _ _ _ _ _ _ _ _ _ _ _ _ _ _\n..\\..\\common\\mysql_operations.py:9: in __init__\n    self.connection = Connection(\nD:\\python3.10.4\\lib\\site-packages\\pymysql\\connections.py:358: in __init__\n    self.connect()\nD:\\python3.10.4\\lib\\site-packages\\pymysql\\connections.py:664: in connect\n    self._request_authentication()\nD:\\python3.10.4\\lib\\site-packages\\pymysql\\connections.py:976: in _request_authentication\n    auth_packet = _auth.caching_sha2_password_auth(self, auth_packet)\nD:\\python3.10.4\\lib\\site-packages\\pymysql\\_auth.py:266: in caching_sha2_password_auth\n    data = sha2_rsa_encrypt(conn.password, conn.salt, conn.server_public_key)\n_ _ _ _ _ _ _ _ _ _ _ _ _ _ _ _ _ _ _ _ _ _ _ _ _ _ _ _ _ _ _ _ _ _ _ _ _ _ _ _\n\npassword = b'123456', salt = b'<v>\"\\x07\\x17mi\\x18Km8yEO\\x1e5x{d'\npublic_key = b'-----BEGIN PUBLIC KEY-----\\nMIIBIjANBgkqhkiG9w0BAQEFAAOCAQ8AMIIBCgKCAQEAvsX8nsvdbWM4cePYsamM\\niBT/Aai30HjN0o0ZWpIjPe...nQpyjpNoClFdEz\\nSGhKaYQ2iy3y+lkCHFS9EzWwzGc9XYJ17FLFh1FpefsfdWFNnuiHBG+W22D+A2Te\\n6wIDAQAB\\n-----END PUBLIC KEY-----\\n'\n\n    def sha2_rsa_encrypt(password, salt, public_key):\n        \"\"\"Encrypt password with salt and public_key.\n    \n        Used for sha256_password and caching_sha2_password.\n        \"\"\"\n        if not _have_cryptography:\n>           raise RuntimeError(\n                \"'cryptography' package is required for sha256_password or\"\n                + \" caching_sha2_password auth methods\"\n            )\nE           RuntimeError: 'cryptography' package is required for sha256_password or caching_sha2_password auth methods\n\nD:\\python3.10.4\\lib\\site-packages\\pymysql\\_auth.py:143: RuntimeError"}, "start": 1715608125184, "stop": 1715608125190, "uuid": "a3c350d1-8189-4110-86d5-29042d24b86a", "historyId": "fcfb8f32404f9bbb4b4c05de0fc2bc8e", "testCaseId": "fcfb8f32404f9bbb4b4c05de0fc2bc8e", "fullName": "script.api.test_add_course.TestAddCourse#test0001", "labels": [{"name": "parentSuite", "value": "script.api"}, {"name": "suite", "value": "test_add_course"}, {"name": "subSuite", "value": "TestAddCourse"}, {"name": "host", "value": "wangtao"}, {"name": "thread", "value": "5868-MainThread"}, {"name": "framework", "value": "pytest"}, {"name": "language", "value": "cpython3"}, {"name": "package", "value": "script.api.test_add_course"}]}